<?xml version="1.0"?>
<robot xmlns:xacro="http://www.ros.org/wiki/xacro" name="grapper">
    <!-- Wheels -->
    <!-- in kg-->
    <!-- Defining the colors used in this robot -->
    <material name="Black">
        <color rgba="0.0 0.0 0.0 1.0" />
    </material>
    <material name="White">
        <color rgba="1.0 1.0 1.0 1.0" />
    </material>
    <!-- CAR -->
    <material name="Blue">
        <color rgba="0 0 0.8 1" />
    </material>
    <material name="Red">
        <color rgba="1 0 0 1" />
    </material>
    <material name="Green">
        <color rgba="0 1 0 1" />
    </material>
    <material name="Yellow">
        <color rgba="1 1 0 1" />
    </material>
    <material name="LightGrey">
        <color rgba="0.6 0.6 0.6 1" />
    </material>
    <material name="DarkGray">
        <color rgba="0.4 0.4 0.4 1" />
    </material>

    <link name="car_base_footprint">
        <inertial>
            <mass value="0.0001" />
            <origin xyz="0 0 0" />
            <inertia ixx="0.0001" ixy="0.0" ixz="0.0" iyy="0.0001" iyz="0.0" izz="0.0001" />
        </inertial>
        <visual>
            <origin rpy="0 0 0" xyz="0 0 0" />
            <geometry>
                <box size="0.001 0.001 0.001" />
            </geometry>
        </visual>
    </link>
    <gazebo reference="car_base_footprint">
        <turnGravityOff>false</turnGravityOff>
    </gazebo>
    <joint name="car_base_footprint_joint" type="fixed">
        <origin rpy="0 0 0" xyz="0 0 0.04" />
        <parent link="car_base_footprint" />
        <child link="car_base_link" />
    </joint>
    <!-- BASE-LINK -->
    <!--Actual
    body/chassis of the robot-->

    <link name="car_base_link">
        <inertial>
            <mass value="10" />
            <origin xyz="0 0 0" />
            <!--The
            3x3 rotational inertia matrix. -->
            <inertia ixx="0.0282916666667" ixy="0" ixz="0" iyy="0.0282916666667" iyz="0"
                izz="0.05625" />
        </inertial>
        <visual>
            <origin rpy="0 0 0" xyz="0 0 0" />
            <geometry>
                <cylinder length="0.02" radius="0.3" />
            </geometry>
            <material name="White" />
        </visual>
        <collision>
            <origin rpy="0 0 0 " xyz="0 0 0" />
            <geometry>
                <cylinder length="0.02" radius="0.3" />
            </geometry>
        </collision>
    </link>


    <gazebo reference="car_base_link">
        <material>Gazebo/White</material>
        <turnGravityOff>false</turnGravityOff>
    </gazebo>

    <!-- Adding Lidar -->

    <link name="car_lidar_link">
        <inertial>
            <mass value="0.5" />
            <origin xyz="0.13 0 0" />
            <inertia ixx="0.001" ixy="0.0" ixz="0.0" iyy="0.001" iyz="0.0" izz="0.001" />
        </inertial>
        <visual>
            <origin xyz="0.13 0 0" />
            <geometry>
                <cylinder length="0.14" radius="0.02" />
            </geometry>
            <material name="Black" />
        </visual>
        <collision>
            <origin xyz="0.13 0 0" />
            <geometry>
                <cylinder length="0.14" radius="0.02" />
            </geometry>
        </collision>
    </link>
    <joint name="car_lidar_joint" type="fixed">
        <origin rpy="0 0 0" xyz="0.13 0 0" />
        <parent link="car_base_link" />
        <child link="car_lidar_link" />
    </joint>
    <gazebo reference="car_lidar_link">
        <sensor name='car_gpu_lidar' type='gpu_lidar'>
            <pose relative_to='car_lidar_frame'>0.05 0 0.15 0 0 0</pose>
            <topic>
                lidar</topic>
            <update_rate>10</update_rate>
            <ray>
                <scan>
                    <horizontal>
                        <samples>640</samples>
                        <resolution>1</resolution>
                        <min_angle>-1.57</min_angle>
                        <max_angle>1.57</max_angle>
                    </horizontal>
                    <vertical>
                        <samples>1</samples>
                        <resolution>1</resolution>
                        <min_angle>0</min_angle>
                        <max_angle>0</max_angle>
                    </vertical>
                </scan>
                <range>
                    <min>0.08</min>
                    <max>10.0</max>
                    <resolution>0.01</resolution>
                </range>
            </ray>
            <always_on>
                1</always_on>
            <visualize>true</visualize>
        </sensor>
    </gazebo>

    <!--fb
    : front, back ; lr: left, right -->
    <link name="car_front_right_wheel">
        <visual>
            <origin rpy="1.57079632679 0  0 " xyz="0 0 0" />
            <geometry>
                <cylinder length="0.02" radius="0.1" />
            </geometry>
            <material name="DarkGray" />
        </visual>
        <collision>
            <origin rpy="1.57079632679 0 0 " xyz="0 0 0" />
            <geometry>
                <cylinder length="0.02" radius="0.1" />
            </geometry>
        </collision>
        <inertial>
            <mass value="2.5" />
            <origin xyz="0 0 0" />
            <inertia ixx="0.00108333333333" ixy="0" ixz="0" iyy="0.00108333333333" iyz="0"
                izz="0.002" />
        </inertial>
    </link>
    <gazebo reference="car_front_right_wheel">
        <mu1 value="1.0" />
        <mu2 value="1.0" />
        <kp value="10000000.0" />
        <kd value="1.0" />
        <fdir1 value="1 0 0" />
        <material>Gazebo/Grey</material>
        <turnGravityOff>false</turnGravityOff>
    </gazebo>
    <joint name="car_front_right_wheel_joint" type="continuous">
        <parent link="car_base_link" />
        <child link="car_front_right_wheel" />
        <origin rpy="0 0 0" xyz="0.0 0.3 0.0" />
        <axis rpy="0  0" xyz="0 1 0" />
        <limit effort="100" velocity="100" />
        <joint_properties damping="0.0" friction="0.0" />
    </joint>
    <!-- Transmission is important to link the joints and the controller -->
    <transmission name="car_front_right_wheel_joint_trans">
        <type>transmission_interface/SimpleTransmission</type>
        <joint name="car_front_right_wheel_joint" />
        <actuator name="car_front_right_wheel_joint_motor">
            <hardwareInterface>EffortJointInterface</hardwareInterface>
            <mechanicalReduction>1</mechanicalReduction>
        </actuator>
    </transmission>
    <!--fb
    : front, back ; lr: left, right -->
    <link name="car_front_left_wheel">
        <visual>
            <origin rpy="1.57079632679 0  0 " xyz="0 0 0" />
            <geometry>
                <cylinder length="0.02" radius="0.1" />
            </geometry>
            <material name="DarkGray" />
        </visual>
        <collision>
            <origin rpy="1.57079632679 0 0 " xyz="0 0 0" />
            <geometry>
                <cylinder length="0.02" radius="0.1" />
            </geometry>
        </collision>
        <inertial>
            <mass value="2.5" />
            <origin xyz="0 0 0" />
            <inertia ixx="0.00108333333333" ixy="0" ixz="0" iyy="0.00108333333333" iyz="0"
                izz="0.002" />
        </inertial>
    </link>
    <gazebo reference="car_front_left_wheel">
        <mu1 value="1.0" />
        <mu2 value="1.0" />
        <kp value="10000000.0" />
        <kd value="1.0" />
        <fdir1 value="1 0 0" />
        <material>Gazebo/Grey</material>
        <turnGravityOff>false</turnGravityOff>
    </gazebo>
    <joint name="car_front_left_wheel_joint" type="continuous">
        <parent link="car_base_link" />
        <child link="car_front_left_wheel" />
        <origin rpy="0 0 0" xyz="0.0 -0.3 0.0" />
        <axis rpy="0  0" xyz="0 1 0" />
        <limit effort="100" velocity="100" />
        <joint_properties damping="0.0" friction="0.0" />
    </joint>
    <!-- Transmission is important to link the joints and the controller -->
    <transmission name="car_front_left_wheel_joint_trans">
        <type>transmission_interface/SimpleTransmission</type>
        <joint name="car_front_left_wheel_joint" />
        <actuator name="car_front_left_wheel_joint_motor">
            <hardwareInterface>EffortJointInterface</hardwareInterface>
            <mechanicalReduction>1</mechanicalReduction>
        </actuator>
    </transmission>
    <!--Caster
    front  -->
    <link name="car_caster_front_link">
        <visual>
            <origin rpy="1.57079632679 0 0" xyz="0 0.02 0" />
            <geometry>
                <sphere radius="0.04" />
            </geometry>
            <material name="Black" />
        </visual>
        <collision>
            <geometry>
                <sphere radius="0.04" />
            </geometry>
            <origin rpy="1.57079632679 0 0" xyz="0 0.02 0" />
        </collision>
        <inertial>
            <mass value="0.5" />
            <origin xyz="0 0 0" />
            <inertia ixx="0.001" ixy="0.0" ixz="0.0" iyy="0.001" iyz="0.0" izz="0.001" />
        </inertial>
    </link>
    <joint name="car_caster_front_joint" type="fixed">
        <parent link="car_base_link" />
        <child link="car_caster_front_link" />
        <origin rpy="-1.57079632679 0 0" xyz="0.2 0.0 0.007" />
    </joint>
    <gazebo reference="car_caster_front_link">
        <turnGravityOff>false</turnGravityOff>
    </gazebo>
    <!--Caster
    back  -->
    <link name="car_caster_back_link">
        <visual>
            <origin rpy="1.57079632679 0 0" xyz="0 0.02 0 " />
            <geometry>
                <sphere radius="0.04" />
            </geometry>
            <material name="Black" />
        </visual>
        <collision>
            <geometry>
                <sphere radius="0.04" />
            </geometry>
            <origin rpy="1.57079632679 0 0" xyz="0 0.02 0 " />
        </collision>
        <inertial>
            <mass value="0.5" />
            <origin xyz="0 0 0" />
            <inertia ixx="0.001" ixy="0.0" ixz="0.0" iyy="0.001" iyz="0.0" izz="0.001" />
        </inertial>
    </link>
    <joint name="car_caster_back_joint" type="fixed">
        <parent link="car_base_link" />
        <child link="car_caster_back_link" />
        <origin rpy="-1.57079632679 0 0" xyz="-0.2 0.0 0.009" />
    </joint>
    <gazebo reference="car_caster_back_link">
        <turnGravityOff>false</turnGravityOff>
    </gazebo>
    <!-- SENSORS -->
    <!-- Differential drive controller  -->
    <gazebo>
        <plugin
            filename="libignition-gazebo-diff-drive-system.so"
            name="ignition::gazebo::systems::DiffDrive">
            <left_joint>car_front_left_wheel_joint</left_joint>
            <right_joint>car_front_right_wheel_joint</right_joint>
            <wheel_separation>0.3</wheel_separation>
            <wheel_radius>0.04</wheel_radius>
            <odom_publish_frequency>1</odom_publish_frequency>
            <topic>cmd_vel</topic>
        </plugin>
    </gazebo>

    <!-- joint between base_link and arm_0_link -->
    <joint name="arm_joint_0" type="fixed">
        <origin rpy="0 0 0" xyz="0 0 0" />
        <parent link="car_base_link" />
        <child link="arm_link_0" />
    </joint>
    <link name="arm_link_0">
        <visual>
            <origin rpy="0 0 0" xyz="0 0 0.02725" />
            <geometry>
                <box size="0.1143 0.1143 0.0545" />
            </geometry>
            <material name="LightGrey" />
        </visual>
        <collision>
            <origin rpy="0 0 0" xyz="0 0 0.02725" />
            <geometry>
                <box size="0.1143 0.1143 0.0545" />
            </geometry>
        </collision>
        <inertial>
            <!-- CENTER OF MASS -->
            <origin rpy="0 0 0" xyz="0 0 0.02725" />
            <mass value="0.2" />
            <!-- box inertia: 1/12*m(y^2+z^2), ... -->
            <inertia ixx="0.000267245666667" ixy="0" ixz="0" iyy="0.000267245666667" iyz="0"
                izz="0.000435483" />
        </inertial>
    </link>
    <joint name="arm_joint_1" type="revolute">
        <parent link="arm_link_0" />
        <child link="arm_link_1" />
        <dynamics damping="3.0" friction="0.3" />
        <limit effort="30.0" lower="-3.1415926535" upper="3.1415926535" velocity="5.0" />
        <origin rpy="0 0 0" xyz="0 0 0.0545" />
        <axis xyz="0 0 1" />
    </joint>
    <link name="arm_link_1">
        <visual>
            <origin rpy="0 0 0" xyz="0 0 0.0615" />
            <geometry>
                <box size="0.0402 0.05 0.123" />
            </geometry>
            <material name="Blue" />
        </visual>
        <collision>
            <origin rpy="0 0 0" xyz="0 0 0.0615" />
            <geometry>
                <box size="0.0402 0.05 0.123" />
            </geometry>
        </collision>
        <inertial>
            <!-- CENTER OF MASS -->
            <origin rpy="0 0 0" xyz="0 0 0.0615" />
            <mass value="0.190421352" />
            <!-- box inertia: 1/12*m(y^2+z^2), ... -->
            <inertia ixx="0.000279744834534" ixy="0" ixz="0" iyy="0.000265717763008" iyz="0"
                izz="6.53151584738e-05" />
        </inertial>
    </link>
    <joint name="arm_joint_2" type="revolute">
        <parent link="arm_link_1" />
        <child link="arm_link_2" />
        <dynamics damping="3.0" friction="0.3" />
        <limit effort="30.0" lower="-1.57079632679" upper="1.57079632679" velocity="5.0" />
        <origin rpy="0 0 0" xyz="0 0 0.123" />
        <axis xyz="0 1 0" />
    </joint>
    <link name="arm_link_2">
        <visual>
            <origin rpy="0 0 0" xyz="0 0 0.1585" />
            <geometry>
                <box size="0.0356 0.05 0.317" />
            </geometry>
            <material name="Red" />
        </visual>
        <collision>
            <origin rpy="0 0 0" xyz="0 0 0.1585" />
            <geometry>
                <box size="0.0356 0.05 0.317" />
            </geometry>
        </collision>
        <inertial>
            <!-- CENTER OF MASS -->
            <origin rpy="0 0 0" xyz="0 0 0.1585" />
            <mass value="0.29302326" />
            <!-- box inertia: 1/12*m(y^2+z^2), ... -->
            <inertia ixx="0.00251484771035" ixy="0" ixz="0" iyy="0.00248474836108" iyz="0"
                izz="9.19936757328e-05" />
        </inertial>
    </link>
    <joint name="arm_joint_3" type="revolute">
        <parent link="arm_link_2" />
        <child link="arm_link_3" />
        <dynamics damping="3.0" friction="0.3" />
        <limit effort="30.0" lower="-1.57079632679" upper="1.57079632679" velocity="5.0" />
        <origin rpy="0 0 0" xyz="0 0 0.317" />
        <axis xyz="0 1 0" />
    </joint>
    <link name="arm_link_3">
        <visual>
            <origin rpy="0 0 0" xyz="0 0 0.101" />
            <geometry>
                <box size="0.0356 0.05 0.202" />
            </geometry>
            <material name="Yellow" />
        </visual>
        <collision>
            <origin rpy="0 0 0" xyz="0 0 0.101" />
            <geometry>
                <box size="0.0356 0.05 0.202" />
            </geometry>
        </collision>
        <inertial>
            <!-- CENTER OF MASS -->
            <origin rpy="0 0 0" xyz="0 0 0.101" />
            <mass value="0.21931466" />
            <!-- box inertia: 1/12*m(y^2+z^2), ... -->
            <inertia ixx="0.000791433503053" ixy="0" ixz="0" iyy="0.000768905501178" iyz="0"
                izz="6.88531064581e-05" />
        </inertial>
    </link>
    <joint name="arm_joint_4" type="revolute">
        <parent link="arm_link_3" />
        <child link="arm_link_4" />
        <dynamics damping="3.0" friction="0.3" />
        <limit effort="30.0" lower="-1.57079632679" upper="1.57079632679" velocity="5.0" />
        <origin rpy="0 0 0" xyz="0 0 0.202" />
        <axis xyz="0 1 0" />
    </joint>
    <link name="arm_link_4">
        <visual>
            <origin rpy="0 0 0" xyz="0 0 0.08025" />
            <geometry>
                <box size="0.0356 0.05 0.1605" />
            </geometry>
            <material name="Green" />
        </visual>
        <collision>
            <origin rpy="0 0 0" xyz="0 0 0.08025" />
            <geometry>
                <box size="0.0356 0.05 0.1605" />
            </geometry>
        </collision>
        <inertial>
            <!-- CENTER OF MASS -->
            <origin rpy="0 0 0" xyz="0 0 0.08025" />
            <mass value="0.15813986" />
            <!-- box inertia: 1/12*m(y^2+z^2), ... -->
            <inertia ixx="0.00037242266488" ixy="0" ixz="0" iyy="0.000356178538461" iyz="0"
                izz="4.96474819141e-05" />
        </inertial>
    </link>
    <joint name="arm_joint_5" type="fixed">
        <parent link="arm_link_4" />
        <child link="arm_link_5" />
        <origin rpy="0 0 0" xyz="0 0 0.1605" />
    </joint>
    <link name="arm_link_5">
        <inertial>
            <!-- CENTER OF MASS -->
            <origin rpy="0 0 0" xyz="0 0 0" />
            <mass value="1e-12" />
            <!-- box inertia: 1/12*m(y^2+z^2), ... -->
            <inertia ixx="1e-12" ixy="0" ixz="0" iyy="1e-12" iyz="0" izz="1e-12" />
        </inertial>
    </link>
</robot>

