<?xml version="1.0"?>
<robot name="arm" xmlns:xacro="http://ros.org/wiki/xacro">
    <material name="omni/Blue">
        <color rgba="0 0 0.8 1" />
    </material>
    <material name="omni/Red">
        <color rgba="1 0 0 1" />
    </material>
    <material name="omni/Green">
        <color rgba="0 1 0 1" />
    </material>
    <material name="omni/Yellow">
        <color rgba="1 1 0 1" />
    </material>
    <material name="omni/LightGrey">
        <color rgba="0.6 0.6 0.6 1" />
    </material>
    <material name="omni/DarkGrey">
        <color rgba="0.4 0.4 0.4 1" />
    </material>
    <link name="link_0">
        <visual>
            <origin rpy="0 0 0" xyz="0 0 0.02725" />
            <geometry>
                <box size="0.1143 0.1143 0.0545" />
            </geometry>
            <material name="omni/LightGrey" />
        </visual>
        <collision>
            <origin rpy="0 0 0" xyz="0 0 0.02725" />
            <geometry>
                <box size="0.1143 0.1143 0.0545" />
            </geometry>
        </collision>
        <inertial>
            <origin rpy="0 0 0" xyz="0 0 0.02725" />
            <mass value="0.2" />
            <inertia ixx="0.000267245666667" ixy="0" ixz="0" iyy="0.000267245666667" iyz="0"
                izz="0.000435483" />
        </inertial>
    </link>
    <joint name="joint_1" type="revolute">
        <parent link="link_0" />
        <child link="link_1" />
        <dynamics damping="3.0" friction="0.3" />
        <limit effort="30.0" lower="-3.1415926535" upper="3.1415926535" velocity="5.0" />
        <origin rpy="0 0 0" xyz="0 0 0.0545" />
        <axis xyz="0 0 1" />
    </joint>
    <link name="link_1">
        <visual>
            <origin rpy="0 0 0" xyz="0 0 0.0615" />
            <geometry>
                <box size="0.0402 0.05 0.123" />
            </geometry>
            <material name="omni/Blue" />
        </visual>
        <collision>
            <origin rpy="0 0 0" xyz="0 0 0.0615" />
            <geometry>
                <box size="0.0402 0.05 0.123" />
            </geometry>
        </collision>
        <inertial>
            <origin rpy="0 0 0" xyz="0 0 0.0615" />
            <mass value="0.190421352" />
            <inertia ixx="0.000279744834534" ixy="0" ixz="0" iyy="0.000265717763008" iyz="0"
                izz="6.53151584738e-05" />
        </inertial>
    </link>
    <joint name="joint_2" type="revolute">
        <parent link="link_1" />
        <child link="link_2" />
        <dynamics damping="3.0" friction="0.3" />
        <limit effort="30.0" lower="-1.57079632679" upper="1.57079632679" velocity="5.0" />
        <origin rpy="0 0 0" xyz="0 0 0.123" />
        <axis xyz="0 1 0" />
    </joint>
    <link name="link_2">
        <visual>
            <origin rpy="0 0 0" xyz="0 0 0.1585" />
            <geometry>
                <box size="0.0356 0.05 0.317" />
            </geometry>
            <material name="omni/Red" />
        </visual>
        <collision>
            <origin rpy="0 0 0" xyz="0 0 0.1585" />
            <geometry>
                <box size="0.0356 0.05 0.317" />
            </geometry>
        </collision>
        <inertial>
            <origin rpy="0 0 0" xyz="0 0 0.1585" />
            <mass value="0.29302326" />
            <inertia ixx="0.00251484771035" ixy="0" ixz="0" iyy="0.00248474836108" iyz="0"
                izz="9.19936757328e-05" />
        </inertial>
    </link>
    <joint name="joint_3" type="revolute">
        <parent link="link_2" />
        <child link="link_3" />
        <dynamics damping="3.0" friction="0.3" />
        <limit effort="30.0" lower="-1.57079632679" upper="1.57079632679" velocity="5.0" />
        <origin rpy="0 0 0" xyz="0 0 0.317" />
        <axis xyz="0 1 0" />
    </joint>
    <link name="link_3">
        <visual>
            <origin rpy="0 0 0" xyz="0 0 0.101" />
            <geometry>
                <box size="0.0356 0.05 0.202" />
            </geometry>
            <material name="omni/Yellow" />
        </visual>
        <collision>
            <origin rpy="0 0 0" xyz="0 0 0.101" />
            <geometry>
                <box size="0.0356 0.05 0.202" />
            </geometry>
        </collision>
        <inertial>
            <origin rpy="0 0 0" xyz="0 0 0.101" />
            <mass value="0.21931466" />
            <inertia ixx="0.000791433503053" ixy="0" ixz="0" iyy="0.000768905501178" iyz="0"
                izz="6.88531064581e-05" />
        </inertial>
    </link>
    <joint name="joint_4" type="revolute">
        <parent link="link_3" />
        <child link="link_4" />
        <dynamics damping="3.0" friction="0.3" />
        <limit effort="30.0" lower="-1.57079632679" upper="1.57079632679" velocity="5.0" />
        <origin rpy="0 0 0" xyz="0 0 0.202" />
        <axis xyz="0 1 0" />
    </joint>
    <link name="link_4">
        <visual>
            <origin rpy="0 0 0" xyz="0 0 0.08025" />
            <geometry>
                <box size="0.0356 0.05 0.1605" />
            </geometry>
            <material name="omni/Green" />
        </visual>
        <collision>
            <origin rpy="0 0 0" xyz="0 0 0.08025" />
            <geometry>
                <box size="0.0356 0.05 0.1605" />
            </geometry>
        </collision>
        <inertial>
            <origin rpy="0 0 0" xyz="0 0 0.08025" />
            <mass value="0.15813986" />
            <inertia ixx="0.00037242266488" ixy="0" ixz="0" iyy="0.000356178538461" iyz="0"
                izz="4.96474819141e-05" />
        </inertial>
    </link>
    <joint name="joint_5" type="fixed">
        <parent link="link_4" />
        <child link="link_5" />
        <origin rpy="0 0 0" xyz="0 0 0.1605" />
    </joint>
    <link name="link_5">
        <inertial>
            <origin rpy="0 0 0" xyz="0 0 0" />
            <mass value="1e-12" />
            <inertia ixx="1e-12" ixy="0" ixz="0" iyy="1e-12" iyz="0" izz="1e-12" />
        </inertial>
    </link>
</robot>
