<?xml version="1.0"?>
<robot xmlns:xacro="http://www.ros.org/wiki/xacro" name="grapper">
    <material name="Black">
        <color rgba="0.0 0.0 0.0 1.0" />
    </material>
    <material name="White">
        <color rgba="1.0 1.0 1.0 1.0" />
    </material>
    <material name="Blue">
        <color rgba="0 0 0.8 1" />
    </material>
    <material name="Red">
        <color rgba="1 0 0 1" />
    </material>
    <material name="Green">
        <color rgba="0 1 0 1" />
    </material>
    <material name="Yellow">
        <color rgba="1 1 0 1" />
    </material>
    <material name="LightGrey">
        <color rgba="0.6 0.6 0.6 1" />
    </material>
    <material name="DarkGray">
        <color rgba="0.4 0.4 0.4 1" />
    </material>

    <link name="base_footprint">
        <inertial>
            <mass value="0.0001" />
            <origin xyz="0 0 0" />
            <inertia ixx="0.0001" ixy="0.0" ixz="0.0" iyy="0.0001" iyz="0.0" izz="0.0001" />
        </inertial>
        <visual>
            <origin rpy="0 0 0" xyz="0 0 0" />
            <geometry>
                <box size="0.001 0.001 0.001" />
            </geometry>
        </visual>
    </link>
    <gazebo reference="base_footprint">
        <turnGravityOff>false</turnGravityOff>
    </gazebo>
    <joint name="base_footprint_joint" type="fixed">
        <origin rpy="0 0 0" xyz="0 0 0.04" />
        <parent link="base_footprint" />
        <child link="base_link" />
    </joint>

    <link name="base_link">
        <inertial>
            <mass value="10" />
            <origin xyz="0 0 0" />
            <!--The
            3x3 rotational inertia matrix. -->
            <inertia ixx="0.0282916666667" ixy="0" ixz="0" iyy="0.0282916666667" iyz="0"
                izz="0.05625" />
        </inertial>
        <visual>
            <origin rpy="0 0 0" xyz="0 0 0" />
            <geometry>
                <cylinder length="0.02" radius="0.3" />
            </geometry>
            <material name="White" />
        </visual>
        <collision>
            <origin rpy="0 0 0 " xyz="0 0 0" />
            <geometry>
                <cylinder length="0.02" radius="0.3" />
            </geometry>
        </collision>
    </link>


    <gazebo reference="base_link">
        <material>Gazebo/White</material>
        <turnGravityOff>false</turnGravityOff>
    </gazebo>

    <!-- Adding Lidar -->

    <link name="lidar_link">
        <inertial>
            <mass value="0.5" />
            <origin xyz="0.13 0 0" />
            <inertia ixx="0.001" ixy="0.0" ixz="0.0" iyy="0.001" iyz="0.0" izz="0.001" />
        </inertial>
        <visual>
            <origin xyz="0.13 0 0" />
            <geometry>
                <cylinder length="0.14" radius="0.02" />
            </geometry>
            <material name="Black" />
        </visual>
        <collision>
            <origin xyz="0.13 0 0" />
            <geometry>
                <cylinder length="0.14" radius="0.02" />
            </geometry>
        </collision>
    </link>
    <joint name="lidar_joint" type="fixed">
        <origin rpy="0 0 0" xyz="0.13 0 0" />
        <parent link="base_link" />
        <child link="lidar_link" />
    </joint>
    <gazebo reference="lidar_link">
        <sensor name=' gpu_lidar' type='gpu_lidar'>
            <pose relative_to=' lidar_frame'>0.05 0 0.15 0 0 0</pose>
            <topic>
                lidar</topic>
            <update_rate>10</update_rate>
            <ray>
                <scan>
                    <horizontal>
                        <samples>640</samples>
                        <resolution>1</resolution>
                        <min_angle>-1.57</min_angle>
                        <max_angle>1.57</max_angle>
                    </horizontal>
                    <vertical>
                        <samples>1</samples>
                        <resolution>1</resolution>
                        <min_angle>0</min_angle>
                        <max_angle>0</max_angle>
                    </vertical>
                </scan>
                <range>
                    <min>0.08</min>
                    <max>10.0</max>
                    <resolution>0.01</resolution>
                </range>
            </ray>
            <always_on>
                1</always_on>
            <visualize>true</visualize>
        </sensor>
    </gazebo>

    <!--fb
    : front, back ; lr: left, right -->
    <link name="front_right_wheel">
        <visual>
            <origin rpy="1.57079632679 0  0 " xyz="0 0 0" />
            <geometry>
                <cylinder length="0.02" radius="0.1" />
            </geometry>
            <material name="DarkGray" />
        </visual>
        <collision>
            <origin rpy="1.57079632679 0 0 " xyz="0 0 0" />
            <geometry>
                <cylinder length="0.02" radius="0.1" />
            </geometry>
        </collision>
        <inertial>
            <mass value="2.5" />
            <origin xyz="0 0 0" />
            <inertia ixx="0.00108333333333" ixy="0" ixz="0" iyy="0.00108333333333" iyz="0"
                izz="0.002" />
        </inertial>
    </link>
    <gazebo reference="front_right_wheel">
        <mu1 value="1.0" />
        <mu2 value="1.0" />
        <kp value="10000000.0" />
        <kd value="1.0" />
        <fdir1 value="1 0 0" />
        <material>Gazebo/Grey</material>
        <turnGravityOff>false</turnGravityOff>
    </gazebo>
    <joint name="front_right_wheel_joint" type="continuous">
        <parent link="base_link" />
        <child link="front_right_wheel" />
        <origin rpy="0 0 0" xyz="0.0 0.3 0.0" />
        <axis rpy="0  0" xyz="0 1 0" />
        <limit effort="100" velocity="100" />
        <joint_properties damping="0.0" friction="0.0" />
    </joint>
    <!-- Transmission is important to link the joints and the controller -->
    <transmission name="front_right_wheel_joint_trans">
        <type>transmission_interface/SimpleTransmission</type>
        <joint name="front_right_wheel_joint" />
        <actuator name="front_right_wheel_joint_motor">
            <hardwareInterface>EffortJointInterface</hardwareInterface>
            <mechanicalReduction>1</mechanicalReduction>
        </actuator>
    </transmission>
    <!--fb
    : front, back ; lr: left, right -->
    <link name="front_left_wheel">
        <visual>
            <origin rpy="1.57079632679 0  0 " xyz="0 0 0" />
            <geometry>
                <cylinder length="0.02" radius="0.1" />
            </geometry>
            <material name="DarkGray" />
        </visual>
        <collision>
            <origin rpy="1.57079632679 0 0 " xyz="0 0 0" />
            <geometry>
                <cylinder length="0.02" radius="0.1" />
            </geometry>
        </collision>
        <inertial>
            <mass value="2.5" />
            <origin xyz="0 0 0" />
            <inertia ixx="0.00108333333333" ixy="0" ixz="0" iyy="0.00108333333333" iyz="0"
                izz="0.002" />
        </inertial>
    </link>
    <gazebo reference="front_left_wheel">
        <mu1 value="1.0" />
        <mu2 value="1.0" />
        <kp value="10000000.0" />
        <kd value="1.0" />
        <fdir1 value="1 0 0" />
        <material>Gazebo/Grey</material>
        <turnGravityOff>false</turnGravityOff>
    </gazebo>
    <joint name="front_left_wheel_joint" type="continuous">
        <parent link="base_link" />
        <child link="front_left_wheel" />
        <origin rpy="0 0 0" xyz="0.0 -0.3 0.0" />
        <axis rpy="0  0" xyz="0 1 0" />
        <limit effort="100" velocity="100" />
        <joint_properties damping="0.0" friction="0.0" />
    </joint>
    <!-- Transmission is important to link the joints and the controller -->
    <transmission name="front_left_wheel_joint_trans">
        <type>transmission_interface/SimpleTransmission</type>
        <joint name="front_left_wheel_joint" />
        <actuator name="front_left_wheel_joint_motor">
            <hardwareInterface>EffortJointInterface</hardwareInterface>
            <mechanicalReduction>1</mechanicalReduction>
        </actuator>
    </transmission>
    <!--Caster
    front  -->
    <link name="caster_front_link">
        <visual>
            <origin rpy="1.57079632679 0 0" xyz="0 0.02 0" />
            <geometry>
                <sphere radius="0.04" />
            </geometry>
            <material name="Black" />
        </visual>
        <collision>
            <geometry>
                <sphere radius="0.04" />
            </geometry>
            <origin rpy="1.57079632679 0 0" xyz="0 0.02 0" />
        </collision>
        <inertial>
            <mass value="0.5" />
            <origin xyz="0 0 0" />
            <inertia ixx="0.001" ixy="0.0" ixz="0.0" iyy="0.001" iyz="0.0" izz="0.001" />
        </inertial>
    </link>
    <joint name="caster_front_joint" type="fixed">
        <parent link="base_link" />
        <child link="caster_front_link" />
        <origin rpy="-1.57079632679 0 0" xyz="0.2 0.0 0.007" />
    </joint>
    <gazebo reference="caster_front_link">
        <turnGravityOff>false</turnGravityOff>
    </gazebo>
    <link name="caster_back_link">
        <visual>
            <origin rpy="1.57079632679 0 0" xyz="0 0.02 0 " />
            <geometry>
                <sphere radius="0.04" />
            </geometry>
            <material name="Black" />
        </visual>
        <collision>
            <geometry>
                <sphere radius="0.04" />
            </geometry>
            <origin rpy="1.57079632679 0 0" xyz="0 0.02 0 " />
        </collision>
        <inertial>
            <mass value="0.5" />
            <origin xyz="0 0 0" />
            <inertia ixx="0.001" ixy="0.0" ixz="0.0" iyy="0.001" iyz="0.0" izz="0.001" />
        </inertial>
    </link>
    <joint name="caster_back_joint" type="fixed">
        <parent link="base_link" />
        <child link="caster_back_link" />
        <origin rpy="-1.57079632679 0 0" xyz="-0.2 0.0 0.009" />
    </joint>
    <gazebo reference="caster_back_link">
        <turnGravityOff>false</turnGravityOff>
    </gazebo>
    <gazebo>
        <plugin
            filename="libignition-gazebo-diff-drive-system.so"
            name="ignition::gazebo::systems::DiffDrive">
            <left_joint> front_left_wheel_joint</left_joint>
            <right_joint> front_right_wheel_joint</right_joint>
            <wheel_separation>0.3</wheel_separation>
            <wheel_radius>0.04</wheel_radius>
            <odom_publish_frequency>1</odom_publish_frequency>
            <topic>cmd_vel</topic>
        </plugin>
    </gazebo>
</robot>

